Workbook

Sheet Summary
B2: ACK Archive Registry — Preservation Progress
B3: Source of truth: Catalog sheet. Update "Preservation Status" column there; this dashboard reflects live counts.
B5: Overall
B6: Total works in catalog | D6: =COUNTA(Catalog!C2:C426) -> 425
B7: Done (in manifest) | D7: =COUNTIF(Catalog!Q2:Q426,"Done")+COUNTIF(Catalog!Q2:Q426,"In Manifest") -> 0
B8: In progress | D8: =COUNTIF(Catalog!Q2:Q426,"Uploading")+COUNTIF(Catalog!Q2:Q426,"Uploaded")+COUNTIF(Catalog!Q2:Q426,"Hash Verified") -> 0
B9: Pending | D9: =COUNTIF(Catalog!Q2:Q426,"Pending") -> 425
B10: Skipped | D10: =COUNTIF(Catalog!Q2:Q426,"Skip") -> 0
B11: Completion % | D11: =(COUNTIF(Catalog!Q2:Q426,"Done")+COUNTIF(Catalog!Q2:Q426,"In Manifest"))/COUNTA(Catalog!C2:C426) -> 0
B14: Per Collection
B15: Collection | C15: Total | D15: Done | E15: In Progress | F15: Pending | G15: % Complete
B16: Starry Nights | C16: =COUNTIF(Catalog!B2:B426,$B16) -> 111 | D16: =COUNTIFS(Catalog!B2:B426,$B16,Catalog!Q2:Q426,"Done")+COUNTIFS(Catalog!B2:B426,$B16,Catalog!Q2:Q426,"In Manifest") -> 0 | E16: =COUNTIFS(Catalog!B2:B426,$B16,Catalog!Q2:Q426,"Uploading")+COUNTIFS(Catalog!B2:B426,$B16,Catalog!Q2:Q426,"Uploaded")+COUNTIFS(Catalog!B2:B426,$B16,Catalog!Q2:Q426,"Hash Verified") -> 0 | F16: =COUNTIFS(Catalog!B2:B426,$B16,Catalog!Q2:Q426,"Pending") -> 111 | G16: =IF(C16=0,0,D16/C16) -> 0
B17: Clown Party | C17: =COUNTIF(Catalog!B2:B426,$B17) -> 12 | D17: =COUNTIFS(Catalog!B2:B426,$B17,Catalog!Q2:Q426,"Done")+COUNTIFS(Catalog!B2:B426,$B17,Catalog!Q2:Q426,"In Manifest") -> 0 | E17: =COUNTIFS(Catalog!B2:B426,$B17,Catalog!Q2:Q426,"Uploading")+COUNTIFS(Catalog!B2:B426,$B17,Catalog!Q2:Q426,"Uploaded")+COUNTIFS(Catalog!B2:B426,$B17,Catalog!Q2:Q426,"Hash Verified") -> 0 | F17: =COUNTIFS(Catalog!B2:B426,$B17,Catalog!Q2:Q426,"Pending") -> 12 | G17: =IF(C17=0,0,D17/C17) -> 0
B18: ACKPFP | C18: =COUNTIF(Catalog!B2:B426,$B18) -> 10 | D18: =COUNTIFS(Catalog!B2:B426,$B18,Catalog!Q2:Q426,"Done")+COUNTIFS(Catalog!B2:B426,$B18,Catalog!Q2:Q426,"In Manifest") -> 0 | E18: =COUNTIFS(Catalog!B2:B426,$B18,Catalog!Q2:Q426,"Uploading")+COUNTIFS(Catalog!B2:B426,$B18,Catalog!Q2:Q426,"Uploaded")+COUNTIFS(Catalog!B2:B426,$B18,Catalog!Q2:Q426,"Hash Verified") -> 0 | F18: =COUNTIFS(Catalog!B2:B426,$B18,Catalog!Q2:Q426,"Pending") -> 10 | G18: =IF(C18=0,0,D18/C18) -> 0
B19: Piano Blossoms | C19: =COUNTIF(Catalog!B2:B426,$B19) -> 6 | D19: =COUNTIFS(Catalog!B2:B426,$B19,Catalog!Q2:Q426,"Done")+COUNTIFS(Catalog!B2:B426,$B19,Catalog!Q2:Q426,"In Manifest") -> 0 | E19: =COUNTIFS(Catalog!B2:B426,$B19,Catalog!Q2:Q426,"Uploading")+COUNTIFS(Catalog!B2:B426,$B19,Catalog!Q2:Q426,"Uploaded")+COUNTIFS(Catalog!B2:B426,$B19,Catalog!Q2:Q426,"Hash Verified") -> 0 | F19: =COUNTIFS(Catalog!B2:B426,$B19,Catalog!Q2:Q426,"Pending") -> 6 | G19: =IF(C19=0,0,D19/C19) -> 0
B20: 1 of 1s | C20: =COUNTIF(Catalog!B2:B426,$B20) -> 15 | D20: =COUNTIFS(Catalog!B2:B426,$B20,Catalog!Q2:Q426,"Done")+COUNTIFS(Catalog!B2:B426,$B20,Catalog!Q2:Q426,"In Manifest") -> 0 | E20: =COUNTIFS(Catalog!B2:B426,$B20,Catalog!Q2:Q426,"Uploading")+COUNTIFS(Catalog!B2:B426,$B20,Catalog!Q2:Q426,"Uploaded")+COUNTIFS(Catalog!B2:B426,$B20,Catalog!Q2:Q426,"Hash Verified") -> 0 | F20: =COUNTIFS(Catalog!B2:B426,$B20,Catalog!Q2:Q426,"Pending") -> 15 | G20: =IF(C20=0,0,D20/C20) -> 0
B21: servants | C21: =COUNTIF(Catalog!B2:B426,$B21) -> 69 | D21: =COUNTIFS(Catalog!B2:B426,$B21,Catalog!Q2:Q426,"Done")+COUNTIFS(Catalog!B2:B426,$B21,Catalog!Q2:Q426,"In Manifest") -> 0 | E21: =COUNTIFS(Catalog!B2:B426,$B21,Catalog!Q2:Q426,"Uploading")+COUNTIFS(Catalog!B2:B426,$B21,Catalog!Q2:Q426,"Uploaded")+COUNTIFS(Catalog!B2:B426,$B21,Catalog!Q2:Q426,"Hash Verified") -> 0 | F21: =COUNTIFS(Catalog!B2:B426,$B21,Catalog!Q2:Q426,"Pending") -> 69 | G21: =IF(C21=0,0,D21/C21) -> 0
B22: Broken Keys | C22: =COUNTIF(Catalog!B2:B426,$B22) -> 48 | D22: =COUNTIFS(Catalog!B2:B426,$B22,Catalog!Q2:Q426,"Done")+COUNTIFS(Catalog!B2:B426,$B22,Catalog!Q2:Q426,"In Manifest") -> 0 | E22: =COUNTIFS(Catalog!B2:B426,$B22,Catalog!Q2:Q426,"Uploading")+COUNTIFS(Catalog!B2:B426,$B22,Catalog!Q2:Q426,"Uploaded")+COUNTIFS(Catalog!B2:B426,$B22,Catalog!Q2:Q426,"Hash Verified") -> 0 | F22: =COUNTIFS(Catalog!B2:B426,$B22,Catalog!Q2:Q426,"Pending") -> 48 | G22: =IF(C22=0,0,D22/C22) -> 0
B23: Warothys | C23: =COUNTIF(Catalog!B2:B426,$B23) -> 26 | D23: =COUNTIFS(Catalog!B2:B426,$B23,Catalog!Q2:Q426,"Done")+COUNTIFS(Catalog!B2:B426,$B23,Catalog!Q2:Q426,"In Manifest") -> 0 | E23: =COUNTIFS(Catalog!B2:B426,$B23,Catalog!Q2:Q426,"Uploading")+COUNTIFS(Catalog!B2:B426,$B23,Catalog!Q2:Q426,"Uploaded")+COUNTIFS(Catalog!B2:B426,$B23,Catalog!Q2:Q426,"Hash Verified") -> 0 | F23: =COUNTIFS(Catalog!B2:B426,$B23,Catalog!Q2:Q426,"Pending") -> 26 | G23: =IF(C23=0,0,D23/C23) -> 0
B24: SuperRare | C24: =COUNTIF(Catalog!B2:B426,$B24) -> 9 | D24: =COUNTIFS(Catalog!B2:B426,$B24,Catalog!Q2:Q426,"Done")+COUNTIFS(Catalog!B2:B426,$B24,Catalog!Q2:Q426,"In Manifest") -> 0 | E24: =COUNTIFS(Catalog!B2:B426,$B24,Catalog!Q2:Q426,"Uploading")+COUNTIFS(Catalog!B2:B426,$B24,Catalog!Q2:Q426,"Uploaded")+COUNTIFS(Catalog!B2:B426,$B24,Catalog!Q2:Q426,"Hash Verified") -> 0 | F24: =COUNTIFS(Catalog!B2:B426,$B24,Catalog!Q2:Q426,"Pending") -> 9 | G24: =IF(C24=0,0,D24/C24) -> 0
B25: Heart You | C25: =COUNTIF(Catalog!B2:B426,$B25) -> 8 | D25: =COUNTIFS(Catalog!B2:B426,$B25,Catalog!Q2:Q426,"Done")+COUNTIFS(Catalog!B2:B426,$B25,Catalog!Q2:Q426,"In Manifest") -> 0 | E25: =COUNTIFS(Catalog!B2:B426,$B25,Catalog!Q2:Q426,"Uploading")+COUNTIFS(Catalog!B2:B426,$B25,Catalog!Q2:Q426,"Uploaded")+COUNTIFS(Catalog!B2:B426,$B25,Catalog!Q2:Q426,"Hash Verified") -> 0 | F25: =COUNTIFS(Catalog!B2:B426,$B25,Catalog!Q2:Q426,"Pending") -> 8 | G25: =IF(C25=0,0,D25/C25) -> 0
B26: Her Favorite Flowers | C26: =COUNTIF(Catalog!B2:B426,$B26) -> 2 | D26: =COUNTIFS(Catalog!B2:B426,$B26,Catalog!Q2:Q426,"Done")+COUNTIFS(Catalog!B2:B426,$B26,Catalog!Q2:Q426,"In Manifest") -> 0 | E26: =COUNTIFS(Catalog!B2:B426,$B26,Catalog!Q2:Q426,"Uploading")+COUNTIFS(Catalog!B2:B426,$B26,Catalog!Q2:Q426,"Uploaded")+COUNTIFS(Catalog!B2:B426,$B26,Catalog!Q2:Q426,"Hash Verified") -> 0 | F26: =COUNTIFS(Catalog!B2:B426,$B26,Catalog!Q2:Q426,"Pending") -> 2 | G26: =IF(C26=0,0,D26/C26) -> 0
B27: Ackstract | C27: =COUNTIF(Catalog!B2:B426,$B27) -> 4 | D27: =COUNTIFS(Catalog!B2:B426,$B27,Catalog!Q2:Q426,"Done")+COUNTIFS(Catalog!B2:B426,$B27,Catalog!Q2:Q426,"In Manifest") -> 0 | E27: =COUNTIFS(Catalog!B2:B426,$B27,Catalog!Q2:Q426,"Uploading")+COUNTIFS(Catalog!B2:B426,$B27,Catalog!Q2:Q426,"Uploaded")+COUNTIFS(Catalog!B2:B426,$B27,Catalog!Q2:Q426,"Hash Verified") -> 0 | F27: =COUNTIFS(Catalog!B2:B426,$B27,Catalog!Q2:Q426,"Pending") -> 4 | G27: =IF(C27=0,0,D27/C27) -> 0
B28: Right Click Print | C28: =COUNTIF(Catalog!B2:B426,$B28) -> 15 | D28: =COUNTIFS(Catalog!B2:B426,$B28,Catalog!Q2:Q426,"Done")+COUNTIFS(Catalog!B2:B426,$B28,Catalog!Q2:Q426,"In Manifest") -> 0 | E28: =COUNTIFS(Catalog!B2:B426,$B28,Catalog!Q2:Q426,"Uploading")+COUNTIFS(Catalog!B2:B426,$B28,Catalog!Q2:Q426,"Uploaded")+COUNTIFS(Catalog!B2:B426,$B28,Catalog!Q2:Q426,"Hash Verified") -> 0 | F28: =COUNTIFS(Catalog!B2:B426,$B28,Catalog!Q2:Q426,"Pending") -> 15 | G28: =IF(C28=0,0,D28/C28) -> 0
B29: Last Orders | C29: =COUNTIF(Catalog!B2:B426,$B29) -> 25 | D29: =COUNTIFS(Catalog!B2:B426,$B29,Catalog!Q2:Q426,"Done")+COUNTIFS(Catalog!B2:B426,$B29,Catalog!Q2:Q426,"In Manifest") -> 0 | E29: =COUNTIFS(Catalog!B2:B426,$B29,Catalog!Q2:Q426,"Uploading")+COUNTIFS(Catalog!B2:B426,$B29,Catalog!Q2:Q426,"Uploaded")+COUNTIFS(Catalog!B2:B426,$B29,Catalog!Q2:Q426,"Hash Verified") -> 0 | F29: =COUNTIFS(Catalog!B2:B426,$B29,Catalog!Q2:Q426,"Pending") -> 25 | G29: =IF(C29=0,0,D29/C29) -> 0
B30: ACK Editions | C30: =COUNTIF(Catalog!B2:B426,$B30) -> 13 | D30: =COUNTIFS(Catalog!B2:B426,$B30,Catalog!Q2:Q426,"Done")+COUNTIFS(Catalog!B2:B426,$B30,Catalog!Q2:Q426,"In Manifest") -> 0 | E30: =COUNTIFS(Catalog!B2:B426,$B30,Catalog!Q2:Q426,"Uploading")+COUNTIFS(Catalog!B2:B426,$B30,Catalog!Q2:Q426,"Uploaded")+COUNTIFS(Catalog!B2:B426,$B30,Catalog!Q2:Q426,"Hash Verified") -> 0 | F30: =COUNTIFS(Catalog!B2:B426,$B30,Catalog!Q2:Q426,"Pending") -> 13 | G30: =IF(C30=0,0,D30/C30) -> 0
B31: The Great Color Study | C31: =COUNTIF(Catalog!B2:B426,$B31) -> 12 | D31: =COUNTIFS(Catalog!B2:B426,$B31,Catalog!Q2:Q426,"Done")+COUNTIFS(Catalog!B2:B426,$B31,Catalog!Q2:Q426,"In Manifest") -> 0 | E31: =COUNTIFS(Catalog!B2:B426,$B31,Catalog!Q2:Q426,"Uploading")+COUNTIFS(Catalog!B2:B426,$B31,Catalog!Q2:Q426,"Uploaded")+COUNTIFS(Catalog!B2:B426,$B31,Catalog!Q2:Q426,"Hash Verified") -> 0 | F31: =COUNTIFS(Catalog!B2:B426,$B31,Catalog!Q2:Q426,"Pending") -> 12 | G31: =IF(C31=0,0,D31/C31) -> 0
B32: Opepen Set 030: a.c.k. | C32: =COUNTIF(Catalog!B2:B426,$B32) -> 6 | D32: =COUNTIFS(Catalog!B2:B426,$B32,Catalog!Q2:Q426,"Done")+COUNTIFS(Catalog!B2:B426,$B32,Catalog!Q2:Q426,"In Manifest") -> 0 | E32: =COUNTIFS(Catalog!B2:B426,$B32,Catalog!Q2:Q426,"Uploading")+COUNTIFS(Catalog!B2:B426,$B32,Catalog!Q2:Q426,"Uploaded")+COUNTIFS(Catalog!B2:B426,$B32,Catalog!Q2:Q426,"Hash Verified") -> 0 | F32: =COUNTIFS(Catalog!B2:B426,$B32,Catalog!Q2:Q426,"Pending") -> 6 | G32: =IF(C32=0,0,D32/C32) -> 0
B33: 6529 | C33: =COUNTIF(Catalog!B2:B426,$B33) -> 3 | D33: =COUNTIFS(Catalog!B2:B426,$B33,Catalog!Q2:Q426,"Done")+COUNTIFS(Catalog!B2:B426,$B33,Catalog!Q2:Q426,"In Manifest") -> 0 | E33: =COUNTIFS(Catalog!B2:B426,$B33,Catalog!Q2:Q426,"Uploading")+COUNTIFS(Catalog!B2:B426,$B33,Catalog!Q2:Q426,"Uploaded")+COUNTIFS(Catalog!B2:B426,$B33,Catalog!Q2:Q426,"Hash Verified") -> 0 | F33: =COUNTIFS(Catalog!B2:B426,$B33,Catalog!Q2:Q426,"Pending") -> 3 | G33: =IF(C33=0,0,D33/C33) -> 0
B34: Made these for your girl | C34: =COUNTIF(Catalog!B2:B426,$B34) -> 1 | D34: =COUNTIFS(Catalog!B2:B426,$B34,Catalog!Q2:Q426,"Done")+COUNTIFS(Catalog!B2:B426,$B34,Catalog!Q2:Q426,"In Manifest") -> 0 | E34: =COUNTIFS(Catalog!B2:B426,$B34,Catalog!Q2:Q426,"Uploading")+COUNTIFS(Catalog!B2:B426,$B34,Catalog!Q2:Q426,"Uploaded")+COUNTIFS(Catalog!B2:B426,$B34,Catalog!Q2:Q426,"Hash Verified") -> 0 | F34: =COUNTIFS(Catalog!B2:B426,$B34,Catalog!Q2:Q426,"Pending") -> 1 | G34: =IF(C34=0,0,D34/C34) -> 0
B35: notxcopy | C35: =COUNTIF(Catalog!B2:B426,$B35) -> 2 | D35: =COUNTIFS(Catalog!B2:B426,$B35,Catalog!Q2:Q426,"Done")+COUNTIFS(Catalog!B2:B426,$B35,Catalog!Q2:Q426,"In Manifest") -> 0 | E35: =COUNTIFS(Catalog!B2:B426,$B35,Catalog!Q2:Q426,"Uploading")+COUNTIFS(Catalog!B2:B426,$B35,Catalog!Q2:Q426,"Uploaded")+COUNTIFS(Catalog!B2:B426,$B35,Catalog!Q2:Q426,"Hash Verified") -> 0 | F35: =COUNTIFS(Catalog!B2:B426,$B35,Catalog!Q2:Q426,"Pending") -> 2 | G35: =IF(C35=0,0,D35/C35) -> 0
B36: ACKek | C36: =COUNTIF(Catalog!B2:B426,$B36) -> 5 | D36: =COUNTIFS(Catalog!B2:B426,$B36,Catalog!Q2:Q426,"Done")+COUNTIFS(Catalog!B2:B426,$B36,Catalog!Q2:Q426,"In Manifest") -> 0 | E36: =COUNTIFS(Catalog!B2:B426,$B36,Catalog!Q2:Q426,"Uploading")+COUNTIFS(Catalog!B2:B426,$B36,Catalog!Q2:Q426,"Uploaded")+COUNTIFS(Catalog!B2:B426,$B36,Catalog!Q2:Q426,"Hash Verified") -> 0 | F36: =COUNTIFS(Catalog!B2:B426,$B36,Catalog!Q2:Q426,"Pending") -> 5 | G36: =IF(C36=0,0,D36/C36) -> 0
B37: Tempted in the Garden | C37: =COUNTIF(Catalog!B2:B426,$B37) -> 1 | D37: =COUNTIFS(Catalog!B2:B426,$B37,Catalog!Q2:Q426,"Done")+COUNTIFS(Catalog!B2:B426,$B37,Catalog!Q2:Q426,"In Manifest") -> 0 | E37: =COUNTIFS(Catalog!B2:B426,$B37,Catalog!Q2:Q426,"Uploading")+COUNTIFS(Catalog!B2:B426,$B37,Catalog!Q2:Q426,"Uploaded")+COUNTIFS(Catalog!B2:B426,$B37,Catalog!Q2:Q426,"Hash Verified") -> 0 | F37: =COUNTIFS(Catalog!B2:B426,$B37,Catalog!Q2:Q426,"Pending") -> 1 | G37: =IF(C37=0,0,D37/C37) -> 0
B38: ROI | C38: =COUNTIF(Catalog!B2:B426,$B38) -> 1 | D38: =COUNTIFS(Catalog!B2:B426,$B38,Catalog!Q2:Q426,"Done")+COUNTIFS(Catalog!B2:B426,$B38,Catalog!Q2:Q426,"In Manifest") -> 0 | E38: =COUNTIFS(Catalog!B2:B426,$B38,Catalog!Q2:Q426,"Uploading")+COUNTIFS(Catalog!B2:B426,$B38,Catalog!Q2:Q426,"Uploaded")+COUNTIFS(Catalog!B2:B426,$B38,Catalog!Q2:Q426,"Hash Verified") -> 0 | F38: =COUNTIFS(Catalog!B2:B426,$B38,Catalog!Q2:Q426,"Pending") -> 1 | G38: =IF(C38=0,0,D38/C38) -> 0
B39: ACKFTW | C39: =COUNTIF(Catalog!B2:B426,$B39) -> 6 | D39: =COUNTIFS(Catalog!B2:B426,$B39,Catalog!Q2:Q426,"Done")+COUNTIFS(Catalog!B2:B426,$B39,Catalog!Q2:Q426,"In Manifest") -> 0 | E39: =COUNTIFS(Catalog!B2:B426,$B39,Catalog!Q2:Q426,"Uploading")+COUNTIFS(Catalog!B2:B426,$B39,Catalog!Q2:Q426,"Uploaded")+COUNTIFS(Catalog!B2:B426,$B39,Catalog!Q2:Q426,"Hash Verified") -> 0 | F39: =COUNTIFS(Catalog!B2:B426,$B39,Catalog!Q2:Q426,"Pending") -> 6 | G39: =IF(C39=0,0,D39/C39) -> 0
B40: Noble Gallery | C40: =COUNTIF(Catalog!B2:B426,$B40) -> 2 | D40: =COUNTIFS(Catalog!B2:B426,$B40,Catalog!Q2:Q426,"Done")+COUNTIFS(Catalog!B2:B426,$B40,Catalog!Q2:Q426,"In Manifest") -> 0 | E40: =COUNTIFS(Catalog!B2:B426,$B40,Catalog!Q2:Q426,"Uploading")+COUNTIFS(Catalog!B2:B426,$B40,Catalog!Q2:Q426,"Uploaded")+COUNTIFS(Catalog!B2:B426,$B40,Catalog!Q2:Q426,"Hash Verified") -> 0 | F40: =COUNTIFS(Catalog!B2:B426,$B40,Catalog!Q2:Q426,"Pending") -> 2 | G40: =IF(C40=0,0,D40/C40) -> 0
B41: experimental - foundation | C41: =COUNTIF(Catalog!B2:B426,$B41) -> 13 | D41: =COUNTIFS(Catalog!B2:B426,$B41,Catalog!Q2:Q426,"Done")+COUNTIFS(Catalog!B2:B426,$B41,Catalog!Q2:Q426,"In Manifest") -> 0 | E41: =COUNTIFS(Catalog!B2:B426,$B41,Catalog!Q2:Q426,"Uploading")+COUNTIFS(Catalog!B2:B426,$B41,Catalog!Q2:Q426,"Uploaded")+COUNTIFS(Catalog!B2:B426,$B41,Catalog!Q2:Q426,"Hash Verified") -> 0 | F41: =COUNTIFS(Catalog!B2:B426,$B41,Catalog!Q2:Q426,"Pending") -> 13 | G41: =IF(C41=0,0,D41/C41) -> 0

Sheet Catalog
A1: Row | B1: Collection | C1: Title | D1: Platform | E1: Chain | F1: Token Standard | G1: Source Contract | H1: Token ID | I1: Edition | J1: Mint Date | K1: Local Thumb Path | L1: Local Full-Res Path | M1: File Type | N1: Original IPFS CID | O1: Arweave TX | P1: SHA-256 Hash | Q1: Preservation Status | R1: Current Collector | S1: Notes
A2: 1 | B2: Starry Nights | C2: Starry Night #1 | H2: 1 | K2: starrynights/elephants_web.jpg | L2: starrynights/elephants.jpg | M2: JPG | Q2: Pending
A3: 2 | B3: Starry Nights | C3: Starry Night #2 | H3: 2 | K3: starrynights/elephants_web.jpg | L3: starrynights/elephants.jpg | M3: JPG | Q3: Pending
A4: 3 | B4: Starry Nights | C4: Starry Night #3 | H4: 3 | K4: starrynights/elephants_web.jpg | L4: starrynights/elephants.jpg | M4: JPG | Q4: Pending
A5: 4 | B5: Starry Nights | C5: Starry Night #4 | H5: 4 | K5: starrynights/elephants_web.jpg | L5: starrynights/elephants.jpg | M5: JPG | Q5: Pending
A6: 5 | B6: Starry Nights | C6: Starry Night #5 | H6: 5 | K6: starrynights/elephants_web.jpg | L6: starrynights/elephants.jpg | M6: JPG | Q6: Pending
A7: 6 | B7: Starry Nights | C7: Starry Night #6 | H7: 6 | K7: starrynights/elephants_web.jpg | L7: starrynights/elephants.jpg | M7: JPG | Q7: Pending
A8: 7 | B8: Starry Nights | C8: Starry Night #7 | H8: 7 | K8: starrynights/elephants_web.jpg | L8: starrynights/elephants.jpg | M8: JPG | Q8: Pending
A9: 8 | B9: Starry Nights | C9: Starry Night #8 | H9: 8 | K9: starrynights/elephants_web.jpg | L9: starrynights/elephants.jpg | M9: JPG | Q9: Pending
A10: 9 | B10: Starry Nights | C10: Starry Night #9 | H10: 9 | K10: starrynights/elephants_web.jpg | L10: starrynights/elephants.jpg | M10: JPG | Q10: Pending
A11: 10 | B11: Starry Nights | C11: Starry Night #10 | H11: 10 | K11: starrynights/elephants_web.jpg | L11: starrynights/elephants.jpg | M11: JPG | Q11: Pending
A12: 11 | B12: Starry Nights | C12: Starry Night #11 | H12: 11 | K12: starrynights/elephants_web.jpg | L12: starrynights/elephants.jpg | M12: JPG | Q12: Pending
A13: 12 | B13: Starry Nights | C13: Starry Night #12 | H13: 12 | K13: starrynights/elephants_web.jpg | L13: starrynights/elephants.jpg | M13: JPG | Q13: Pending
... A112: 111 | B112: Starry Nights | C112: Starry Night #111 | H112: 111 | K112: starrynights/elephants_web.jpg | L112: starrynights/elephants.jpg | M112: JPG | Q112: Pending
A113: 112 | B113: Clown Party | C113: self portrait - tin man | D113: Own / Other | E113: Ethereum | G113: 0x4772fb1ed333777cf4a062ffcda2d25ce3e1029c | H113: 5 | K113: clownparty/web/tinman_physical_web.jpg | L113: clownparty/web/tinman_physical_web.jpg | M113: JPG | Q113: Pending | R113: punk8868
A114: 113 | B114: Clown Party | C114: self portrait - tin man (digital) | D114: Own / Other | E114: Ethereum | G114: 0x4772fb1ed333777cf4a062ffcda2d25ce3e1029c | H114: 5 | K114: clownparty/web/tinman_digital_web.jpg | L114: https://arweave.net/bPVYlbj_IyQn3Rw2oIKm2PWyJTWTyYlfcgX3dfnFbnU | Q114: Pending
A115: 114 | B115: Clown Party | C115: Heavy Mettle | D115: Own / Other | E115: Ethereum | G115: 0x4772fb1ed333777cf4a062ffcda2d25ce3e1029c | H115: 2 | K115: clownparty/web/heavy_mettle_physical_web.jpg | L115: clownparty/web/heavy_mettle_physical_web.jpg | M115: JPG | Q115: Pending | R115: hittman_
A116: 115 | B116: Clown Party | C116: Heavy Mettle (digital) | D116: Own / Other | E116: Ethereum | G116: 0x4772fb1ed333777cf4a062ffcda2d25ce3e1029c | H116: 2 | K116: clownparty/web/heavy_mettle_digital_web.jpg | L116: https://arweave.net/lmfiRkcV8y0iOYzE_zDFabIR1yiphdK-OUF9SKpwp4c | Q116: Pending
A117: 116 | B117: Clown Party | C117: Showtime | D117: Own / Other | E117: Ethereum | G117: 0x4772fb1ed333777cf4a062ffcda2d25ce3e1029c | H117: 4 | K117: clownparty/web/showtime_physical_web.jpg | L117: clownparty/web/showtime_physical_web.jpg | M117: JPG | Q117: Pending | R117: foretwenty
A118: 117 | B118: Clown Party | C118: Showtime (digital) | D118: Own / Other | E118: Ethereum | G118: 0x4772fb1ed333777cf4a062ffcda2d25ce3e1029c | H118: 4 | K118: clownparty/web/showtime_digital_web.jpg | L118: https://arweave.net/54BzS3c7AJdtzQwKvobS6Nr7X0PxRFsDQO6hcZI98Nc | Q118: Pending
A119: 118 | B119: Clown Party | C119: spectACKular | D119: Own / Other | E119: Ethereum | G119: 0x4772fb1ed333777cf4a062ffcda2d25ce3e1029c | H119: 3 | K119: clownparty/web/spectackular_physical_web.jpg | L119: clownparty/web/spectackular_physical_web.jpg | M119: JPG | Q119: Pending
A120: 119 | B120: Clown Party | C120: spectACKular (digital) | D120: Own / Other | E120: Ethereum | G120: 0x4772fb1ed333777cf4a062ffcda2d25ce3e1029c | H120: 3 | K120: clownparty/web/spectackular_digital_web.jpg | L120: https://arweave.net/RaykHYiKi-2SJkq0Vas49M0AJinUexcUp4TJYTKaIu4 | Q120: Pending
A121: 120 | B121: Clown Party | C121: Pink Carousel | D121: Own / Other | E121: Ethereum | G121: 0x4772fb1ed333777cf4a062ffcda2d25ce3e1029c | H121: 6 | K121: clownparty/web/pink_carousel_physical_web.jpg | L121: clownparty/web/pink_carousel_physical_web.jpg | M121: JPG | Q121: Pending
A122: 121 | B122: Clown Party | C122: Pink Carousel (digital) | D122: Own / Other | E122: Ethereum | G122: 0x4772fb1ed333777cf4a062ffcda2d25ce3e1029c | H122: 6 | K122: clownparty/web/pink_carousel_digital_web.jpg | L122: https://arweave.net/3sdRZ9bzZVNkGKVEC-rdCvSfkFr1AQdgu2x21yQfXqg | Q122: Pending
A123: 122 | B123: Clown Party | C123: Goodnight Circus | D123: Own / Other | E123: Ethereum | G123: 0x4772fb1ed333777cf4a062ffcda2d25ce3e1029c | H123: 1 | K123: clownparty/web/goodnight_circus_physical_web.jpg | L123: clownparty/web/goodnight_circus_physical_web.jpg | M123: JPG | Q123: Pending
A124: 123 | B124: Clown Party | C124: Goodnight Circus (digital) | D124: Own / Other | E124: Ethereum | G124: 0x4772fb1ed333777cf4a062ffcda2d25ce3e1029c | H124: 1 | K124: clownparty/web/goodnight_circus_digital_web.jpg | L124: https://arweave.net/ATA8fFKjhLGyKw8uVkmGEI8AWMEcLd13U0Bh62BR_Yc | Q124: Pending
A125: 124 | B125: ACKPFP | C125: ~timeReaper~ | D125: Own / Other | E125: Ethereum | G125: 0x7d0874f682c42f0fe907baf7785d9dcb5a0b1285 | H125: 1 | K125: ackpfp/timreaper.gif | L125: https://arweave.net/hv5XUE9_hZqhjhGT3qbqBSvV-8eQ_yi3kOexAkhsz30 | Q125: Pending
A126: 125 | B126: ACKPFP | C126: serSingularity | D126: Own / Other | E126: Ethereum | G126: 0x7d0874f682c42f0fe907baf7785d9dcb5a0b1285 | H126: 5 | K126: ackpfp/sersingularity.gif | L126: https://arweave.net/QTX3eFu7Y9peBIRAlq5L92dksjBw-Kw7rYt3bbyNGcc | Q126: Pending
A127: 126 | B127: ACKPFP | C127: misterShady | D127: Own / Other | E127: Ethereum | G127: 0x7d0874f682c42f0fe907baf7785d9dcb5a0b1285 | H127: 3 | K127: ackpfp/mistershady.gif | L127: https://arweave.net/Eal93gHFj44PiHPGYzlaz__fcRIp-r_NfQmIjVCl80g | Q127: Pending
A128: 127 | B128: ACKPFP | C128: laserEyes | D128: Own / Other | E128: Ethereum | G128: 0x7d0874f682c42f0fe907baf7785d9dcb5a0b1285 | H128: 2 | K128: ackpfp/lasereyes.gif | L128: https://arweave.net/b_4A7HyuwLaqxC00PoMsBLEBDPh9MhMh0JlXoNSsAR0 | Q128: Pending
A129: 128 | B129: ACKPFP | C129: morning star | D129: Own / Other | E129: Ethereum | G129: 0x7d0874f682c42f0fe907baf7785d9dcb5a0b1285 | H129: 9 | K129: ackpfp/morningstar.gif | L129: https://arweave.net/Gh2dfHaGsNR5P33VClFwDzYVbxYmp6UuqixyPcNWA8o | Q129: Pending
A130: 129 | B130: ACKPFP | C130: skullBoy | D130: Own / Other | E130: Ethereum | G130: 0x7d0874f682c42f0fe907baf7785d9dcb5a0b1285 | H130: 6 | K130: ackpfp/skullboy.gif | L130: https://arweave.net/a48EQDKqsN20CrXNfw5w4Sags_Vhh3EoiWBGX9kumU0 | Q130: Pending
A131: 130 | B131: ACKPFP | C131: no one | D131: Own / Other | E131: Ethereum | G131: 0x7d0874f682c42f0fe907baf7785d9dcb5a0b1285 | H131: 10 | K131: ackpfp/noone.gif | L131: https://arweave.net/dgNSgZHkO6pB4XxnuoHEo3B7J2hnRGvBVdflO4Sv0IU | Q131: Pending
A132: 131 | B132: ACKPFP | C132: cringe pepe | D132: Own / Other | E132: Ethereum | G132: 0x7d0874f682c42f0fe907baf7785d9dcb5a0b1285 | H132: 8 | K132: ackpfp/web/cringepepe_web.jpg | L132: https://arweave.net/T9TzoW3yqHi9ZBw3cmiXfGTVU8CzDJgdrJ30SdzMO0I | Q132: Pending | R132: VincentVanDough
A133: 132 | B133: ACKPFP | C133: fireFace | D133: Own / Other | E133: Ethereum | G133: 0x7d0874f682c42f0fe907baf7785d9dcb5a0b1285 | H133: 4 | K133: ackpfp/fireface.gif | L133: https://arweave.net/TgXQCUVtQn_UQ5r_6tsfZyac0Mau2YFmwFGqoy3SnNQ | Q133: Pending
A134: 133 | B134: ACKPFP | C134: greg | D134: Own / Other | E134: Ethereum | G134: 0x7d0874f682c42f0fe907baf7785d9dcb5a0b1285 | H134: 7 | K134: ackpfp/greg.gif | L134: https://arweave.net/iwe8737PCZcJsHj61jntF_MagWawadrOtFyWesoWok8 | Q134: Pending
A135: 134 | B135: Piano Blossoms | C135: self portrait in the garden of the Muse | D135: Own / Other | E135: Ethereum | G135: 0x728d7a5133068e3c7e5afe72de8999076bc940f9 | H135: 6 | I135: 1 of 1 | K135: piano_blossoms/web/self_portrait_physical_web.jpg | L135: piano_blossoms/self_portrait_in_the_garden_of_the_Muse/self_portrait_in_the_garden_of_the_Muse.jpg | M135: JPG | Q135: Pending | R135: BBA
A136: 135 | B136: Piano Blossoms | C136: Muse Blossoms | D136: Own / Other | E136: Ethereum | G136: 0x728d7a5133068e3c7e5afe72de8999076bc940f9 | H136: 4 | I136: 1 of 1 | K136: piano_blossoms/web/muse_blossoms_physical_web.jpg | L136: piano_blossoms/muse_blossoms/Muse_blossoms.jpg | M136: JPG | Q136: Pending | R136: Hivemind Capital
A137: 136 | B137: Piano Blossoms | C137: Wonderland | D137: Own / Other | E137: Ethereum | G137: 0x728d7a5133068e3c7e5afe72de8999076bc940f9 | H137: 1 | I137: 1 of 1 | K137: piano_blossoms/web/wonderland_physical_web.jpg | L137: piano_blossoms/wonderland/Wonderland.jpg | M137: JPG | Q137: Pending | R137: Hivemind Capital
A138: 137 | B138: Piano Blossoms | C138: Golden Afternoon | D138: Own / Other | E138: Ethereum | G138: 0x728d7a5133068e3c7e5afe72de8999076bc940f9 | H138: 3 | I138: 1 of 1 | K138: piano_blossoms/web/golden_afternoon_physical_web.jpg | L138: piano_blossoms/golden_afternoon/Golden_Afternoon.jpg | M138: JPG | Q138: Pending | R138: Hivemind Capital
...

Sheet How to Use
B2: ACK Archive Registry — Catalog Workbook
B4: This workbook is the data spine for ACK's permanent preservation system. It drives the Arweave uploads, the on-chain merkle root, and the public manifest JSON.
B6: Workflow
B8: 1. For each row, upload the Local Full-Res Path (or Local Thumb Path if no full-res exists) to Arweave.
B9: 2. Paste the Arweave TX hash into the Arweave TX column.
B10: 3. Compute the SHA-256 of the uploaded file and paste into SHA-256 Hash. (shasum -a 256 path/to/file)
B11: 4. For Foundation/SuperRare works, find the existing IPFS CID from the tokenURI and paste into Original IPFS CID.
B12: 5. Update Preservation Status as you go: Pending > Uploading > Uploaded > Hash Verified > In Manifest > Done.
B13: 6. The Summary sheet updates live as you fill rows.
B15: Column Legend
B17: Columns in BLUE (Original IPFS CID, Arweave TX, SHA-256 Hash, Notes) are for you to fill in.
B18: Columns in BLACK are auto-populated from your gallery's COLLECTIONS data.
... B44: 5. Optionally renounce ownership to make the archive permanent/immutable.
